<?xml version="1.0"?>
<!--URDF MODEL point robot-->
<robot xmlns:xacro="http://wiki.ros.org/xacro">
  <xacro:macro name="point_robot"
  params="joint_limited prefix origin_frame color sphere_radius:=${0.015} ">

<!--
  <material name="black">
    <color rgba="1 1 1 0.9"/>
  </material> 
  <material name="red">
    <color rgba="1 0 0 0.9"/>
  </material>
  <material name="green">
    <color rgba="0 1 0 0.9"/>
  </material>
  <material name="blue">
    <color rgba="0 0 1 0.9"/>
  </material> -->

  <joint name="${prefix}world2cartesian" type="fixed">
    <parent link="${origin_frame}"/>
    <child link="${prefix}link_Z"/>
    <origin xyz="0 0 0" />
  </joint>
  
  <link name="${prefix}link_Z"/>
  <joint name="${prefix}from_Z_to_X" type="fixed">
    <parent link="${prefix}link_Z"/>
    <child link="${prefix}link_X"/>
    <xacro:unless value="${joint_limited}">
    <limit effort="1000.0" velocity="0.5" lower="-9999999.9"  upper="9999999.9" />
    </xacro:unless>
    <xacro:if value="${joint_limited}">
    <limit effort="1000.0" velocity="0.5" lower="0" upper="1.0"/>
    </xacro:if>
    <axis xyz = "0 0 1" />
    <origin rpy="0 0 0" xyz="0.5 0 0.0"/>
  </joint>
  
  <link name="${prefix}link_X"/>
  <joint name="${prefix}from_X_to_fake" type="prismatic">
    <parent link="${prefix}link_X"/>
    <child link="${prefix}link_fake"/>
    <xacro:unless value="${joint_limited}">
    <limit effort="1000.0" velocity="0.5" lower="-9999999.9"  upper="9999999.9" />
    </xacro:unless>
    <xacro:if value="${joint_limited}">
    <limit effort="1000.0" velocity="0.5" lower="0" upper="1.0"/>
    </xacro:if>
    <axis xyz = "1 0 0" />
    <origin rpy="0 0 0" xyz="-0.5 0 0"/>
    <limit effort="1000.0" lower="0" upper="1" velocity="0.5"/>
  </joint>
  
  <link name="${prefix}link_fake"/>
  <joint name="${prefix}from_fake_to_Y" type="prismatic">
    <parent link="${prefix}link_fake"/>
    <child link="${prefix}link_Y"/>
    <xacro:unless value="${joint_limited}">
    <limit effort="1000.0" velocity="0.5" lower="-9999999.9"  upper="9999999.9" />
    </xacro:unless>
    <xacro:if value="${joint_limited}">
    <limit effort="1000.0" velocity="0.5" lower="0" upper="1.0"/>
    </xacro:if>
    <axis xyz = "0 1 0" />
    <origin rpy="0 0 0" xyz="0 -0.5 0"/>
    <limit effort="1000.0" lower="0" upper="1" velocity="0.5"/>
  </joint>
  
  <link name="${prefix}link_Y"/>
  <joint name="${prefix}from_Y_to_end" type="fixed">
    <parent link="${prefix}link_Y"/>
    <child link="${prefix}end_effector"/>
    <origin rpy="0 0 0" xyz="0 0.5 0"/>
  </joint>
  
  <link name="${prefix}end_effector">
    <visual>
      <geometry>
        <sphere radius="${sphere_radius}"/>
      </geometry>
      <origin rpy="0 0 0" xyz="0 0 0"/>
      <material name="${color}"/>
    </visual>
    <collision>
      <origin rpy="0 0 0" xyz="0 0 0"/>
      <geometry>
        <sphere radius="${sphere_radius}"/>
      </geometry>
    </collision>
  </link>
  </xacro:macro>

</robot>


