<?xml version="1.0" ?>
<!-- =================================================================================== -->
<!-- |    This document was autogenerated by xacro from /home/marco/projects/cells_ws/src/planar_cartesian_robot/planar_cartesian_robot_description/urdf/point4robots.urdf.xacro | -->
<!-- |    EDITING THIS FILE BY HAND IS NOT RECOMMENDED                                 | -->
<!-- =================================================================================== -->
<!--URDF MODEL 2 point robots-->
<robot name="point2robots">
    <material name="black">
        <color rgba="1 1 1 0.9" />
    </material>
    <material name="red">
        <color rgba="1 0 0 0.9" />
    </material>
    <material name="green">
        <color rgba="0 1 0 0.9" />
    </material>
    <material name="blue">
        <color rgba="0 0 1 0.9" />
    </material>
    <link name="world" />
    <!--
  <material name="black">
    <color rgba="1 1 1 0.9"/>
  </material> 
  <material name="red">
    <color rgba="1 0 0 0.9"/>
  </material>
  <material name="green">
    <color rgba="0 1 0 0.9"/>
  </material>
  <material name="blue">
    <color rgba="0 0 1 0.9"/>
  </material> -->
    <joint name="r_world2cartesian" type="fixed">
        <parent link="world" />
        <child link="r_link_Z" />
        <origin xyz="0 0 0" />
    </joint>
    <link name="r_link_Z" />
    <joint name="r_from_Z_to_X" type="fixed">
        <parent link="r_link_Z" />
        <child link="r_link_X" />
        <limit effort="1000.0" lower="0" upper="1.0" velocity="0.5" />
        <axis xyz="0 0 1" />
        <origin rpy="0 0 0" xyz="0.5 0 0.0" />
    </joint>
    <link name="r_link_X" />
    <joint name="r_from_X_to_fake" type="prismatic">
        <parent link="r_link_X" />
        <child link="r_link_fake" />
        <limit effort="1000.0" lower="0" upper="1.0" velocity="0.5" />
        <axis xyz="1 0 0" />
        <origin rpy="0 0 0" xyz="-0.5 0 0" />
        <limit effort="1000.0" lower="0" upper="1" velocity="0.5" />
    </joint>
    <link name="r_link_fake" />
    <joint name="r_from_fake_to_Y" type="prismatic">
        <parent link="r_link_fake" />
        <child link="r_link_Y" />
        <limit effort="1000.0" lower="0" upper="1.0" velocity="0.5" />
        <axis xyz="0 1 0" />
        <origin rpy="0 0 0" xyz="0 -0.5 0" />
        <limit effort="1000.0" lower="0" upper="1" velocity="0.5" />
    </joint>
    <link name="r_link_Y" />
    <joint name="r_from_Y_to_end" type="fixed">
        <parent link="r_link_Y" />
        <child link="r_end_effector" />
        <origin rpy="0 0 0" xyz="0 0.5 0" />
    </joint>
    <link name="r_end_effector">
        <visual>
            <geometry>
                <sphere radius="0.015" />
            </geometry>
            <origin rpy="0 0 0" xyz="0 0 0" />
            <material name="red" />
        </visual>
        <collision>
            <origin rpy="0 0 0" xyz="0 0 0" />
            <geometry>
                <sphere radius="0.015" />
            </geometry>
        </collision>
        <inertial>
            <mass value="0.1" />
            <origin xyz="0 0 0" rpy="0 0 0" />
            <inertia ixx="0.03" iyy="0.03" izz="0.03" ixy="0.0" ixz="0.0" iyz="0.0" />
        </inertial>
    </link>
    <!--
  <material name="black">
    <color rgba="1 1 1 0.9"/>
  </material> 
  <material name="red">
    <color rgba="1 0 0 0.9"/>
  </material>
  <material name="green">
    <color rgba="0 1 0 0.9"/>
  </material>
  <material name="blue">
    <color rgba="0 0 1 0.9"/>
  </material> -->
    <joint name="g_world2cartesian" type="fixed">
        <parent link="world" />
        <child link="g_link_Z" />
        <origin xyz="0 0 0" />
    </joint>
    <link name="g_link_Z" />
    <joint name="g_from_Z_to_X" type="fixed">
        <parent link="g_link_Z" />
        <child link="g_link_X" />
        <limit effort="1000.0" lower="0" upper="1.0" velocity="0.5" />
        <axis xyz="0 0 1" />
        <origin rpy="0 0 0" xyz="0.5 0 0.0" />
    </joint>
    <link name="g_link_X" />
    <joint name="g_from_X_to_fake" type="prismatic">
        <parent link="g_link_X" />
        <child link="g_link_fake" />
        <limit effort="1000.0" lower="0" upper="1.0" velocity="0.5" />
        <axis xyz="1 0 0" />
        <origin rpy="0 0 0" xyz="-0.5 0 0" />
        <limit effort="1000.0" lower="0" upper="1" velocity="0.5" />
    </joint>
    <link name="g_link_fake" />
    <joint name="g_from_fake_to_Y" type="prismatic">
        <parent link="g_link_fake" />
        <child link="g_link_Y" />
        <limit effort="1000.0" lower="0" upper="1.0" velocity="0.5" />
        <axis xyz="0 1 0" />
        <origin rpy="0 0 0" xyz="0 -0.5 0" />
        <limit effort="1000.0" lower="0" upper="1" velocity="0.5" />
    </joint>
    <link name="g_link_Y" />
    <joint name="g_from_Y_to_end" type="fixed">
        <parent link="g_link_Y" />
        <child link="g_end_effector" />
        <origin rpy="0 0 0" xyz="0 0.5 0" />
    </joint>
    <link name="g_end_effector">
        <visual>
            <geometry>
                <sphere radius="0.015" />
            </geometry>
            <origin rpy="0 0 0" xyz="0 0 0" />
            <material name="green" />
        </visual>
        <collision>
            <origin rpy="0 0 0" xyz="0 0 0" />
            <geometry>
                <sphere radius="0.015" />
            </geometry>
        </collision>
        <inertial>
            <mass value="0.1" />
            <origin xyz="0 0 0" rpy="0 0 0" />
            <inertia ixx="0.03" iyy="0.03" izz="0.03" ixy="0.0" ixz="0.0" iyz="0.0" />
        </inertial>
    </link>
    <!--
  <material name="black">
    <color rgba="1 1 1 0.9"/>
  </material> 
  <material name="red">
    <color rgba="1 0 0 0.9"/>
  </material>
  <material name="green">
    <color rgba="0 1 0 0.9"/>
  </material>
  <material name="blue">
    <color rgba="0 0 1 0.9"/>
  </material> -->
    <joint name="b_world2cartesian" type="fixed">
        <parent link="world" />
        <child link="b_link_Z" />
        <origin xyz="0 0 0" />
    </joint>
    <link name="b_link_Z" />
    <joint name="b_from_Z_to_X" type="fixed">
        <parent link="b_link_Z" />
        <child link="b_link_X" />
        <limit effort="1000.0" lower="0" upper="1.0" velocity="0.5" />
        <axis xyz="0 0 1" />
        <origin rpy="0 0 0" xyz="0.5 0 0.0" />
    </joint>
    <link name="b_link_X" />
    <joint name="b_from_X_to_fake" type="prismatic">
        <parent link="b_link_X" />
        <child link="b_link_fake" />
        <limit effort="1000.0" lower="0" upper="1.0" velocity="0.5" />
        <axis xyz="1 0 0" />
        <origin rpy="0 0 0" xyz="-0.5 0 0" />
        <limit effort="1000.0" lower="0" upper="1" velocity="0.5" />
    </joint>
    <link name="b_link_fake" />
    <joint name="b_from_fake_to_Y" type="prismatic">
        <parent link="b_link_fake" />
        <child link="b_link_Y" />
        <limit effort="1000.0" lower="0" upper="1.0" velocity="0.5" />
        <axis xyz="0 1 0" />
        <origin rpy="0 0 0" xyz="0 -0.5 0" />
        <limit effort="1000.0" lower="0" upper="1" velocity="0.5" />
    </joint>
    <link name="b_link_Y" />
    <joint name="b_from_Y_to_end" type="fixed">
        <parent link="b_link_Y" />
        <child link="b_end_effector" />
        <origin rpy="0 0 0" xyz="0 0.5 0" />
    </joint>
    <link name="b_end_effector">
        <visual>
            <geometry>
                <sphere radius="0.015" />
            </geometry>
            <origin rpy="0 0 0" xyz="0 0 0" />
            <material name="blue" />
        </visual>
        <collision>
            <origin rpy="0 0 0" xyz="0 0 0" />
            <geometry>
                <sphere radius="0.015" />
            </geometry>
        </collision>
        <inertial>
            <mass value="0.1" />
            <origin xyz="0 0 0" rpy="0 0 0" />
            <inertia ixx="0.03" iyy="0.03" izz="0.03" ixy="0.0" ixz="0.0" iyz="0.0" />
        </inertial>
    </link>
    <!--
  <material name="black">
    <color rgba="1 1 1 0.9"/>
  </material> 
  <material name="red">
    <color rgba="1 0 0 0.9"/>
  </material>
  <material name="green">
    <color rgba="0 1 0 0.9"/>
  </material>
  <material name="blue">
    <color rgba="0 0 1 0.9"/>
  </material> -->
    <joint name="k_world2cartesian" type="fixed">
        <parent link="world" />
        <child link="k_link_Z" />
        <origin xyz="0 0 0" />
    </joint>
    <link name="k_link_Z" />
    <joint name="k_from_Z_to_X" type="fixed">
        <parent link="k_link_Z" />
        <child link="k_link_X" />
        <limit effort="1000.0" lower="0" upper="1.0" velocity="0.5" />
        <axis xyz="0 0 1" />
        <origin rpy="0 0 0" xyz="0.5 0 0.0" />
    </joint>
    <link name="k_link_X" />
    <joint name="k_from_X_to_fake" type="prismatic">
        <parent link="k_link_X" />
        <child link="k_link_fake" />
        <limit effort="1000.0" lower="0" upper="1.0" velocity="0.5" />
        <axis xyz="1 0 0" />
        <origin rpy="0 0 0" xyz="-0.5 0 0" />
        <limit effort="1000.0" lower="0" upper="1" velocity="0.5" />
    </joint>
    <link name="k_link_fake" />
    <joint name="k_from_fake_to_Y" type="prismatic">
        <parent link="k_link_fake" />
        <child link="k_link_Y" />
        <limit effort="1000.0" lower="0" upper="1.0" velocity="0.5" />
        <axis xyz="0 1 0" />
        <origin rpy="0 0 0" xyz="0 -0.5 0" />
        <limit effort="1000.0" lower="0" upper="1" velocity="0.5" />
    </joint>
    <link name="k_link_Y" />
    <joint name="k_from_Y_to_end" type="fixed">
        <parent link="k_link_Y" />
        <child link="k_end_effector" />
        <origin rpy="0 0 0" xyz="0 0.5 0" />
    </joint>
    <link name="k_end_effector">
        <visual>
            <geometry>
                <sphere radius="0.015" />
            </geometry>
            <origin rpy="0 0 0" xyz="0 0 0" />
            <material name="black" />
        </visual>
        <collision>
            <origin rpy="0 0 0" xyz="0 0 0" />
            <geometry>
                <sphere radius="0.015" />
            </geometry>
        </collision>
        <inertial>
            <mass value="0.1" />
            <origin xyz="0 0 0" rpy="0 0 0" />
            <inertia ixx="0.03" iyy="0.03" izz="0.03" ixy="0.0" ixz="0.0" iyz="0.0" />
        </inertial>
    </link>
    <transmission name="trans_r_from_X_to_fake">
        <type>transmission_interface/SimpleTransmission</type>
        <joint name="r_from_X_to_fake">
            <hardwareInterface>hardware_interface/EffortJointInterface</hardwareInterface>
        </joint>
        <actuator name="r_from_X_to_fake_motor">
            <hardwareInterface>hardware_interface/EffortJointInterface</hardwareInterface>
            <mechanicalReduction>1</mechanicalReduction>
        </actuator>
    </transmission>
    <transmission name="trans_r_from_fake_to_Y">
        <type>transmission_interface/SimpleTransmission</type>
        <joint name="r_from_fake_to_Y">
            <hardwareInterface>hardware_interface/EffortJointInterface</hardwareInterface>
        </joint>
        <actuator name="r_from_fake_to_Y_motor">
            <hardwareInterface>hardware_interface/EffortJointInterface</hardwareInterface>
            <mechanicalReduction>1</mechanicalReduction>
        </actuator>
    </transmission>
    <transmission name="trans_g_from_X_to_fake">
        <type>transmission_interface/SimpleTransmission</type>
        <joint name="g_from_X_to_fake">
            <hardwareInterface>hardware_interface/EffortJointInterface</hardwareInterface>
        </joint>
        <actuator name="g_from_X_to_fake_motor">
            <hardwareInterface>hardware_interface/EffortJointInterface</hardwareInterface>
            <mechanicalReduction>1</mechanicalReduction>
        </actuator>
    </transmission>
    <transmission name="trans_g_from_fake_to_Y">
        <type>transmission_interface/SimpleTransmission</type>
        <joint name="g_from_fake_to_Y">
            <hardwareInterface>hardware_interface/EffortJointInterface</hardwareInterface>
        </joint>
        <actuator name="g_from_fake_to_Y_motor">
            <hardwareInterface>hardware_interface/EffortJointInterface</hardwareInterface>
            <mechanicalReduction>1</mechanicalReduction>
        </actuator>
    </transmission>
    <transmission name="trans_b_from_X_to_fake">
        <type>transmission_interface/SimpleTransmission</type>
        <joint name="b_from_X_to_fake">
            <hardwareInterface>hardware_interface/EffortJointInterface</hardwareInterface>
        </joint>
        <actuator name="b_from_X_to_fake_motor">
            <hardwareInterface>hardware_interface/EffortJointInterface</hardwareInterface>
            <mechanicalReduction>1</mechanicalReduction>
        </actuator>
    </transmission>
    <transmission name="trans_b_from_fake_to_Y">
        <type>transmission_interface/SimpleTransmission</type>
        <joint name="b_from_fake_to_Y">
            <hardwareInterface>hardware_interface/EffortJointInterface</hardwareInterface>
        </joint>
        <actuator name="b_from_fake_to_Y_motor">
            <hardwareInterface>hardware_interface/EffortJointInterface</hardwareInterface>
            <mechanicalReduction>1</mechanicalReduction>
        </actuator>
    </transmission>
    <transmission name="trans_k_from_X_to_fake">
        <type>transmission_interface/SimpleTransmission</type>
        <joint name="k_from_X_to_fake">
            <hardwareInterface>hardware_interface/EffortJointInterface</hardwareInterface>
        </joint>
        <actuator name="k_from_X_to_fake_motor">
            <hardwareInterface>hardware_interface/EffortJointInterface</hardwareInterface>
            <mechanicalReduction>1</mechanicalReduction>
        </actuator>
    </transmission>
    <transmission name="trans_k_from_fake_to_Y">
        <type>transmission_interface/SimpleTransmission</type>
        <joint name="k_from_fake_to_Y">
            <hardwareInterface>hardware_interface/EffortJointInterface</hardwareInterface>
        </joint>
        <actuator name="k_from_fake_to_Y_motor">
            <hardwareInterface>hardware_interface/EffortJointInterface</hardwareInterface>
            <mechanicalReduction>1</mechanicalReduction>
        </actuator>
    </transmission>
    <gazebo>
        <plugin name="gazebo_ros_control">
            <robotNamespace>/</robotNamespace>
        </plugin>
    </gazebo>
</robot>

